[2025-06-02T17:11:24.974+0000] {logging_mixin.py:151} INFO - Changing /opt/***/logs/dag_id=inference_pipeline/run_id=scheduled__2025-06-01T17:11:07.006818+00:00/task_id=load_model permission to 509
[2025-06-02T17:11:24.975+0000] {logging_mixin.py:151} INFO - Failed to change /opt/***/logs/dag_id=inference_pipeline/run_id=scheduled__2025-06-01T17:11:07.006818+00:00/task_id=load_model permission to 509: [Errno 1] Operation not permitted: '/opt/***/logs/dag_id=inference_pipeline/run_id=scheduled__2025-06-01T17:11:07.006818+00:00/task_id=load_model'
[2025-06-02T17:11:25.002+0000] {logging_mixin.py:151} INFO - Changing /opt/***/logs/dag_id=inference_pipeline/run_id=scheduled__2025-06-01T17:11:07.006818+00:00/task_id=load_model permission to 509
[2025-06-02T17:11:25.002+0000] {logging_mixin.py:151} INFO - Failed to change /opt/***/logs/dag_id=inference_pipeline/run_id=scheduled__2025-06-01T17:11:07.006818+00:00/task_id=load_model permission to 509: [Errno 1] Operation not permitted: '/opt/***/logs/dag_id=inference_pipeline/run_id=scheduled__2025-06-01T17:11:07.006818+00:00/task_id=load_model'
[2025-06-02T17:11:25.038+0000] {taskinstance.py:1157} INFO - Dependencies all met for dep_context=non-requeueable deps ti=<TaskInstance: inference_pipeline.load_model scheduled__2025-06-01T17:11:07.006818+00:00 [queued]>
[2025-06-02T17:11:25.046+0000] {taskinstance.py:1157} INFO - Dependencies all met for dep_context=requeueable deps ti=<TaskInstance: inference_pipeline.load_model scheduled__2025-06-01T17:11:07.006818+00:00 [queued]>
[2025-06-02T17:11:25.046+0000] {taskinstance.py:1359} INFO - Starting attempt 1 of 2
[2025-06-02T17:11:25.135+0000] {taskinstance.py:1380} INFO - Executing <Task(PythonOperator): load_model> on 2025-06-01 17:11:07.006818+00:00
[2025-06-02T17:11:25.140+0000] {standard_task_runner.py:57} INFO - Started process 334 to run task
[2025-06-02T17:11:25.144+0000] {standard_task_runner.py:84} INFO - Running: ['***', 'tasks', 'run', 'inference_pipeline', 'load_model', 'scheduled__2025-06-01T17:11:07.006818+00:00', '--job-id', '3', '--raw', '--subdir', 'DAGS_FOLDER/inference_dag.py', '--cfg-path', '/tmp/tmpzin57w75']
[2025-06-02T17:11:25.147+0000] {standard_task_runner.py:85} INFO - Job 3: Subtask load_model
[2025-06-02T17:11:25.189+0000] {logging_mixin.py:151} INFO - Changing /opt/***/logs/dag_id=inference_pipeline/run_id=scheduled__2025-06-01T17:11:07.006818+00:00/task_id=load_model permission to 509
[2025-06-02T17:11:25.189+0000] {logging_mixin.py:151} INFO - Failed to change /opt/***/logs/dag_id=inference_pipeline/run_id=scheduled__2025-06-01T17:11:07.006818+00:00/task_id=load_model permission to 509: [Errno 1] Operation not permitted: '/opt/***/logs/dag_id=inference_pipeline/run_id=scheduled__2025-06-01T17:11:07.006818+00:00/task_id=load_model'
[2025-06-02T17:11:25.192+0000] {task_command.py:415} INFO - Running <TaskInstance: inference_pipeline.load_model scheduled__2025-06-01T17:11:07.006818+00:00 [running]> on host aaa95e2cbf82
[2025-06-02T17:11:25.253+0000] {taskinstance.py:1660} INFO - Exporting env vars: AIRFLOW_CTX_DAG_OWNER='***' AIRFLOW_CTX_DAG_ID='inference_pipeline' AIRFLOW_CTX_TASK_ID='load_model' AIRFLOW_CTX_EXECUTION_DATE='2025-06-01T17:11:07.006818+00:00' AIRFLOW_CTX_TRY_NUMBER='1' AIRFLOW_CTX_DAG_RUN_ID='scheduled__2025-06-01T17:11:07.006818+00:00'
[2025-06-02T17:11:25.255+0000] {logging_mixin.py:151} INFO - Модель не найдена по пути /opt/***/data/model.pkl. Создание новой модели...
[2025-06-02T17:11:25.258+0000] {taskinstance.py:1935} ERROR - Task failed with exception
Traceback (most recent call last):
  File "/home/airflow/.local/lib/python3.8/site-packages/airflow/operators/python.py", line 192, in execute
    return_value = self.execute_callable()
  File "/home/airflow/.local/lib/python3.8/site-packages/airflow/operators/python.py", line 209, in execute_callable
    return self.python_callable(*self.op_args, **self.op_kwargs)
  File "/opt/airflow/dags/inference_dag.py", line 51, in load_model
    from sklearn.ensemble import RandomForestClassifier
ModuleNotFoundError: No module named 'sklearn'
[2025-06-02T17:11:25.269+0000] {taskinstance.py:1398} INFO - Marking task as UP_FOR_RETRY. dag_id=inference_pipeline, task_id=load_model, execution_date=20250601T171107, start_date=20250602T171125, end_date=20250602T171125
[2025-06-02T17:11:25.284+0000] {standard_task_runner.py:104} ERROR - Failed to execute job 3 for task load_model (No module named 'sklearn'; 334)
[2025-06-02T17:11:25.317+0000] {local_task_job_runner.py:228} INFO - Task exited with return code 1
[2025-06-02T17:11:25.335+0000] {taskinstance.py:2776} INFO - 0 downstream tasks scheduled from follow-on schedule check
